Workbook

Sheet Cover
D3: Jeyavishnu Wastewater Recycle & Reuse Project, Tirupur
D7: UWR RoU Scope: 5 Monitoring Period: 01/01/2014-31/12/2024 Crediting Period: 2014-2024 UNDP Human Development Indicator:0.644(India) Uncertainty factor : 0.98 RoUs Generated During 1st Monitoring Period: 01/01/2014-31/12/2024

Sheet RoUs
A1: JEYAVISHNU CLOTHING PRIVATE LTD
A2: DAILY FLOW DETAILS FROM YEAR ( 2014 TO 2024 )
A3: SL NO | B3: MONTH & YEAR | C3: INLET FLOW M3/DAY | D3: OUTLET ETP FLOW M3/DAY | E3: TREATED WATER M3/DAY | F3: RoUs | G3: Year wise
A4: 1 | B4: 41640 | C4: 11510 | D4: 13069 | E4: 13177.83 | F4: =E4*0.98 -> 12914.273 | G4: =SUM(F4:F15) -> 202449.7
A5: 2 | B5: 41671 | C5: 13510 | D5: 13105.2 | E5: 13086.318 | F5: =E5*0.98 -> 12824.592 | I5: According to the RoU Standard, PP has accounted 1% each as the uncertainty factor in inflow and outflow volumes to be conservative. Hence an uncertainity factor of 0.98 is applied to all ROUs.
A6: 3 | B6: 41699 | C6: 14371 | D6: 13105 | E6: 14532 | F6: =E6*0.98 -> 14241.36
A7: 4 | B7: 41730 | C7: =10639+6228-1654 -> 15213 | D7: 14635 | E7: 15569 | F7: =E7*0.98 -> 15257.62
A8: 5 | B8: 41760 | C8: =11549+5993-1624 -> 15918 | D8: 16298 | E8: 16620 | F8: =E8*0.98 -> 16287.6
A9: 6 | B9: 41791 | C9: 14271 | D9: 14305 | E9: 14417 | F9: =E9*0.98 -> 14128.66
A10: 7 | B10: 41821 | C10: =(11077+5930)-2816 -> 14191 | D10: 14136 | E10: 19727 | F10: =E10*0.98 -> 19332.46
A11: 8 | B11: 41852 | C11: 11841 | D11: 11168 | E11: 11105 | F11: =E11*0.98 -> 10882.9
A12: 9 | B12: 41883 | C12: 21211 | D12: 18921 | E12: 18988 | F12: =E12*0.98 -> 18608.24
A13: 10 | B13: 41913 | C13: 20255 | D13: 20070 | E13: 20962 | F13: =E13*0.98 -> 20542.76
A14: 11 | B14: 41944 | C14: 23512.77 | D14: 22526 | E14: 23845.175 | F14: =E14*0.98 -> 23368.272
A15: 12 | B15: 41974 | C15: 26262 | D15: 24776 | E15: 24552 | F15: =E15*0.98 -> 24060.96
A16: 13 | B16: 42005 | C16: 18838 | D16: 18131 | E16: 18133 | F16: =E16*0.98 -> 17770.34 | G16: =SUM(F16:F27) -> 276828.44
A17: 14 | B17: 42036 | C17: 16010 | D17: 14973 | E17: 14901 | F17: =E17*0.98 -> 14602.98
A18: 15 | B18: 42064 | C18: 21224 | D18: 21576 | E18: 21263 | F18: =E18*0.98 -> 20837.74
A19: 16 | B19: 42095 | C19: 23259 | D19: 23760 | E19: 23245 | F19: =E19*0.98 -> 22780.1
A20: 17 | B20: 42125 | C20: 25345 | D20: 25203 | E20: 23968 | F20: =E20*0.98 -> 23488.64
A21: 18 | B21: 42156 | C21: 25031 | D21: 24680 | E21: 24390 | F21: =E21*0.98 -> 23902.2
A22: 19 | B22: 42186 | C22: 26469 | D22: 26867 | E22: 25888 | F22: =E22*0.98 -> 25370.24
A23: 20 | B23: 42217 | C23: 25851 | D23: 25635 | E23: 24957 | F23: =E23*0.98 -> 24457.86
A24: 21 | B24: 42248 | C24: 26537 | D24: 27471 | E24: 26754 | F24: =E24*0.98 -> 26218.92
A25: 22 | B25: 42278 | C25: 29146 | D25: 31451 | E25: 29823 | F25: =E25*0.98 -> 29226.54
A26: 23 | B26: 42309 | C26: 20832 | D26: 22260 | E26: 20663 | F26: =E26*0.98 -> 20249.74
A27: 24 | B27: 42339 | C27: 28204 | D27: 29999 | E27: 28493 | F27: =E27*0.98 -> 27923.14
A28: 25 | B28: 42370 | C28: 22015 | D28: 24007 | E28: 22839 | F28: =E28*0.98 -> 22382.22 | G28: =SUM(F28:F39) -> 301964.46
A29: 26 | B29: 42401 | C29: 28537 | D29: 26779 | E29: 27731 | F29: =E29*0.98 -> 27176.38
A30: 27 | B30: 42430 | C30: 31183 | D30: 29648 | E30: 29043 | F30: =E30*0.98 -> 28462.14
A31: 28 | B31: 42461 | C31: 25946 | D31: 23892 | E31: 24717 | F31: =E31*0.98 -> 24222.66
A32: 29 | B32: 42491 | C32: 28019 | D32: 26436 | E32: 26108 | F32: =E32*0.98 -> 25585.84
A33: 30 | B33: 42522 | C33: 29062 | D33: 28050 | E33: 28287 | F33: =E33*0.98 -> 27721.26
A34: 31 | B34: 42552 | C34: 29308 | D34: 27383 | E34: 28635 | F34: =E34*0.98 -> 28062.3
A35: 32 | B35: 42583 | C35: 29056 | D35: 28329 | E35: 29122 | F35: =E35*0.98 -> 28539.56
A36: 33 | B36: 42614 | C36: 30209 | D36: 29892 | E36: 29021 | F36: =E36*0.98 -> 28440.58
A37: 34 | B37: 42644 | C37: 24756 | D37: 22233 | E37: 22700 | F37: =E37*0.98 -> 22246
A38: 35 | B38: 42675 | C38: 24856 | D38: 23479 | E38: 23901 | F38: =E38*0.98 -> 23422.98
A39: 36 | B39: 42705 | C39: 17550 | D39: 17629 | E39: 16023 | F39: =E39*0.98 -> 15702.54
A40: 37 | B40: 42736 | C40: 17550 | D40: 17629 | E40: 16023 | F40: =E40*0.98 -> 15702.54 | G40: =SUM(F40:F51) -> 425386.64
...

Sheet Year Wise
D4: Year | E4: Total ROUs
E5: (1000 liters)/yr
E6: UCR Cap (1 million RoUs/yr
D7: 2014 | E7: =RoUs!G4 -> 202449.7
D8: 2015 | E8: =RoUs!G16 -> 276828.44
D9: 2016 | E9: =RoUs!G28 -> 301964.46
D10: 2017 | E10: =RoUs!G40 -> 425386.64
D11: 2018 | E11: =RoUs!G52 -> 455678.44
D12: 2019 | E12: =RoUs!G64 -> 506962.82
D13: 2020 | E13: =RoUs!G76 -> 400637.56
D14: 2021 | E14: =RoUs!G88 -> 495842.34
D15: 2022 | E15: =RoUs!G100 -> 481351.79
D16: 2023 | E16: =RoUs!G112 -> 539776.48
D17: 2024 | E17: =RoUs!G124 -> 724032.82
D18: Total RoUs | E18: =SUM(E7:E17) -> 4810911.5
